Workbook

Sheet Tichete
A1: ID tichet | B1: Data deschiderii | C1: Canal | D1: Categorie | E1: Funcționalitate | F1: Titlu | G1: Descriere | H1: Pași de verificare | I1: Severitate | J1: Nr. raportări clienți | K1: Versiune raportată | L1: Status | M1: Versiune fix | N1: Data livrării fix-ului | O1: Data închiderii | P1: Zile până la fix | Q1: Echipă responsabilă | R1: Tichet legat | S1: Cuvinte cheie recenzii (EN)
A2: WB-1001 | B2: 46028 | C2: Web | D2: Notificări | E2: Status zbor | F2: Pagina „Status zbor” afișează poarta veche după schimbarea porții | G2: După schimbarea porții, pagina „Status zbor” afișează în continuare poarta veche. Clienții merg la poarta greșită. | I2: Mare | J2: 120 | K2: 3.0.0 | L2: Rezolvat – fix livrat | M2: 3.1.0 | N2: 46053 | P2: =IF(N2="","",N2-B2) -> 25 | Q2: Echipa Mobile | S2: wrong gate shown; gate change not updated; flight status shows old gate
A3: WB-1002 | B3: 46055 | C3: Web | D3: Rambursări | E3: BeeCredit | F3: Rambursarea se face automat în BeeCredit în loc de card | G3: Opțiunea implicită de rambursare este creditul în cont, iar clientul nu poate alege cardul. | I3: Mare | J3: 125 | K3: 3.1.0 | L3: Rezolvat – fix livrat | M3: 3.3.0 | N3: 46093 | P3: =IF(N3="","",N3-B3) -> 38 | Q3: Echipa Rambursări | S3: refund as credit only; forced voucher; wizz credit instead of refund
A4: WB-1003 | B4: 46066 | C4: Web | D4: Check-in | E4: Boarding pass | F4: Butonul „Descarcă boarding pass” nu face nimic | G4: În pagina rezervării, butonul „Descarcă boarding pass” nu descarcă PDF-ul și nu afișează nicio eroare. | I4: Mare | J4: 55 | K4: 3.1.0 | L4: Rezolvat – fix livrat | M4: 3.3.0 | N4: 46093 | P4: =IF(N4="","",N4-B4) -> 27 | Q4: Echipa Mobile | S4: boarding pass download not working; can't download boarding pass; boarding pass button does nothing
A5: WB-1004 | B5: 46067 | C5: Web | D5: Notificări | E5: Status zbor | F5: Pagina „Status zbor” afișează poarta veche după schimbarea porții | G5: După schimbarea porții, pagina „Status zbor” afișează în continuare poarta veche. Clienții merg la poarta greșită. | I5: Mare | J5: 266 | K5: 3.1.0 | L5: În lucru | P5: =IF(N5="","",N5-B5) | Q5: Echipa Mobile | R5: WB-1001 | S5: wrong gate shown; gate change not updated; flight status shows old gate
A6: WB-1005 | B6: 46084 | C6: Email | D6: Cont | E6: Profil | F6: Modificarea numelui pe bilet cere taxă chiar și pentru o greșeală de tastare | G6: Corectarea unei litere din nume este taxată ca schimbare completă de nume. | I6: Medie | J6: 71 | K6: 3.2.0 | L6: Rezolvat – fix livrat | M6: 3.3.0 | N6: 46093 | P6: =IF(N6="","",N6-B6) -> 9 | Q6: Echipa Rezervări | S6: name change fee; typo in name charged; correct name on ticket
A7: WB-1006 | B7: 46106 | C7: Web | D7: Rambursări | E7: BeeCredit | F7: Rambursarea se face automat în BeeCredit în loc de card | G7: Opțiunea implicită de rambursare este creditul în cont, iar clientul nu poate alege cardul. | I7: Mare | J7: 46 | K7: 3.3.0 | L7: Rezolvat – fix livrat | M7: 3.5.0 | N7: 46133 | P7: =IF(N7="","",N7-B7) -> 27 | Q7: Echipa Rambursări | R7: WB-1002 | S7: refund as credit only; forced voucher; wizz credit instead of refund
A8: WB-1007 | B8: 46108 | C8: Email | D8: Check-in | E8: Boarding pass | F8: Butonul „Descarcă boarding pass” nu face nimic | G8: În pagina rezervării, butonul „Descarcă boarding pass” nu descarcă PDF-ul și nu afișează nicio eroare. | I8: Mare | J8: 138 | K8: 3.3.0 | L8: În lucru | P8: =IF(N8="","",N8-B8) | Q8: Echipa Mobile | R8: WB-1003 | S8: boarding pass download not working; can't download boarding pass; boarding pass button does nothing
A9: WB-1008 | B9: 46110 | C9: Web | D9: Bagaje | E9: Adăugare bagaj | F9: Prețul bagajului de cală crește la plată | G9: Prețul bagajului de cală afișat la alegerea bagajului e mai mic decât cel încasat la pasul de plată. | H9: 1. Pe pagina principală caută zboruri București (OTP) → Barcelona (BCN), data 2026-11-13, 1 pasager. 2. Alege zborul WB 541 și completează numele pasagerului. 3. La „Bagaje și extra” alege „Bagaj de cală 20 kg” și notează prețul afișat (189 lei). 4. Mergi până la pasul „Plată”. Rezultat așteptat: în tabelul de plată, rândul „Bagaj de cală 20 kg” are același preț ca la alegerea bagajului (189 lei). | I9: Medie | J9: 30 | K9: 3.3.0 | L9: Rezolvat – fix livrat | M9: 3.6.0 | N9: 46153 | P9: =IF(N9="","",N9-B9) -> 43 | Q9: Echipa Ancillaries | S9: baggage price after booking; checked bag expensive; luggage fee increase
A10: WB-1009 | B10: 46124 | C10: Web | D10: Plăți | E10: Plată card | F10: Plata e respinsă, dar suma e blocată pe card | G10: Clientul vede „Plată eșuată”, dar rezervarea apare totuși în „Călătoriile mele”. Clientul reîncearcă și ajunge să plătească de două ori. | I10: Critică | J10: 86 | K10: 3.4.0 | L10: Rezolvat – fix livrat | M10: 3.6.0 | N10: 46153 | P10: =IF(N10="","",N10-B10) -> 29 | Q10: Echipa Plăți | S10: payment failed but charged; double charged; money taken booking failed
A11: WB-1010 | B11: 46124 | C11: Rețele sociale | D11: Plăți | E11: Conversie valutară | F11: Prețul în RON diferă între căutare și plată | G11: Tariful afișat la căutare este în RON, dar la plată apare o sumă mai mare, din cauza unui curs de schimb vechi. | I11: Medie | J11: 89 | K11: 3.4.0 | L11: Rezolvat – fix livrat | M11: 3.6.0 | N11: 46153 | P11: =IF(N11="","",N11-B11) -> 29 | Q11: Echipa Plăți | S11: price changed at checkout; currency conversion wrong; hidden fees checkout
A12: WB-1011 | B12: 46126 | C12: Call center | D12: Rezervare | E12: Priority | F12: Priority Boarding nu apare pe boarding pass după upgrade | G12: Clientul cumpără Priority după rezervare, dar boarding pass-ul nu se actualizează și e oprit la poartă. | I12: Mare | J12: 149 | K12: 3.4.0 | L12: Rezolvat – fix livrat | M12: 3.6.0 | N12: 46153 | P12: =IF(N12="","",N12-B12) -> 27 | Q12: Echipa Ancillaries | S12: priority boarding not on boarding pass; paid priority refused; priority not showing
A13: WB-1012 | B13: 46129 | C13: Rețele sociale | D13: Bagaje | E13: Dimensiuni bagaj | F13: Ghidul de dimensiuni pentru bagajul de mână e neclar | G13: Pagina de bagaje nu arată clar diferența dintre geanta mică gratuită și trolerul de 10 kg. Clienții plătesc taxe la poartă. | I13: Mică | J13: 41 | K13: 3.4.0 | L13: Închis – nu se reproduce | O13: 46141 | P13: =IF(N13="","",N13-B13) | Q13: Echipa Conținut | S13: cabin bag size; carry-on fee at gate; hand luggage charged gate
A14: WB-1013 | B14: 46129 | C14: Email | D14: Rezervare | E14: Selecție locuri | F14: Harta de locuri nu se încarcă pentru zborurile cu A321neo | G14: La aeronavele A321neo harta rămâne goală și clientul nu poate alege loc. | I14: Mare | J14: 255 | K14: 3.4.0 | L14: Închis – nu se reproduce | O14: 46134 | P14: =IF(N14="","",N14-B14) | Q14: Echipa Rezervări | S14: seat map not loading; can't select seat; seat selection error
A15: WB-1014 | B15: 46137 | C15: Call center | D15: Aplicație | E15: Călătoriile mele | F15: Pagina rezervării rămâne albă la deschiderea din „Călătoriile mele” | G15: Când clientul deschide o rezervare din „Călătoriile mele”, pagina rămâne albă și detaliile zborului nu se încarcă. | I15: Critică | J15: 376 | K15: 3.5.0 | L15: Rezolvat – fix livrat | M15: 3.7.0 | N15: 46172 | P15: =IF(N15="","",N15-B15) -> 35 | Q15: Echipa Mobile | S15: booking page blank; my trips not loading; white screen booking
A16: WB-1015 | B16: 46138 | C16: Rețele sociale | D16: Rezervare | E16: Căutare zboruri | F16: Căutarea flexibilă afișează zboruri anulate | G16: Calendarul de tarife arată prețuri pentru zboruri deja anulate din orar. | I16: Medie | J16: 34 | K16: 3.5.0 | L16: Rezolvat – fix livrat | M16: 3.6.0 | N16: 46153 | P16: =IF(N16="","",N16-B16) -> 15 | Q16: Echipa Rezervări | S16: flight cancelled after booking; booked cancelled flight; search shows cancelled
A17: WB-1016 | B17: 46144 | C17: Web | D17: Rezervare | E17: Selecție locuri | F17: Harta de locuri nu se încarcă pentru zborurile cu A321neo | G17: La aeronavele A321neo harta rămâne goală și clientul nu poate alege loc. | H17: 1. Pe pagina principală caută zboruri București (OTP) → Barcelona (BCN), data 2026-11-13, 1 pasager. 2. Alege zborul WB 541 (A321neo). 3. Completează numele pasagerului, apasă „Continuă” până la pasul „Locuri”. Rezultat așteptat: harta locurilor se afișează și un loc poate fi selectat; nu rămâne blocată la „Se încarcă harta locurilor…”. | I17: Mare | J17: 81 | K17: 3.5.0 | L17: Rezolvat – fix livrat | M17: 3.8.0 | N17: 46191 | P17: =IF(N17="","",N17-B17) -> 47 | Q17: Echipa Rezervări | R17: WB-1013 | S17: seat map not loading; can't select seat; seat selection error
A18: WB-1017 | B18: 46146 | C18: Email | D18: Rezervare | E18: Selecție locuri | F18: Familiile sunt așezate separat deși au plătit locuri | G18: Locurile alese pentru copii sunt reatribuite la check-in, iar copiii ajung separați de părinți. | I18: Mare | J18: 8 | K18: 3.5.0 | L18: Rezolvat – fix livrat | M18: 3.7.0 | N18: 46172 | P18: =IF(N18="","",N18-B18) -> 26 | Q18: Echipa Rezervări | S18: family seated apart; kids separated from parents; paid seats changed
A19: WB-1018 | B19: 46151 | C19: Rețele sociale | D19: Notificări | E19: Întârzieri | F19: Avertizarea de întârziere nu apare la zborurile întârziate peste 3 ore | G19: În pagina rezervării nu apare avertizarea de întârziere și nici link-ul pentru cererea de compensație, deși zborul are peste 3 ore întârziere. | I19: Mare | J19: 295 | K19: 3.5.0 | L19: Rezolvat – fix livrat | M19: 3.7.0 | N19: 46172 | P19: =IF(N19="","",N19-B19) -> 21 | Q19: Echipa Operațiuni Digitale | S19: no delay notice; delay not shown; compensation link missing
A20: WB-1019 | B20: 46151 | C20: Web | D20: Asistență specială | E20: PRM | F20: Cererea de asistență specială nu se salvează în rezervare | G20: După trimiterea formularului de asistență cu scaun rulant apare mesajul de confirmare, dar cererea nu apare în detaliile rezervării. | I20: Critică | J20: 87 | K20: 3.5.0 | L20: Închis – nu se reproduce | O20: 46160 | P20: =IF(N20="","",N20-B20) | Q20: Echipa Operațiuni Digitale | S20: special assistance request lost; wheelchair request not saved; PRM request missing
A21: WB-1020 | B21: 46152 | C21: Rețele sociale | D21: Bagaje | E21: Dimensiuni bagaj | F21: Ghidul de dimensiuni pentru bagajul de mână e neclar | G21: Pagina de bagaje nu arată clar diferența dintre geanta mică gratuită și trolerul de 10 kg. Clienții plătesc taxe la poartă. | I21: Mică | J21: 59 | K21: 3.5.0 | L21: Rezolvat – fix livrat | M21: 3.8.0 | N21: 46191 | P21: =IF(N21="","",N21-B21) -> 39 | Q21: Echipa Conținut | R21: WB-1012 | S21: cabin bag size; carry-on fee at gate; hand luggage charged gate
A22: WB-1021 | B22: 46156 | C22: Web | D22: Rambursări | E22: Cerere rambursare | F22: Cererile de rambursare rămân „În procesare” peste 30 de zile | G22: După anularea zborului, cererile de rambursare nu trec de starea „În procesare”. Clienții nu primesc nicio actualizare. | I22: Critică | J22: 330 | K22: 3.6.0 | L22: Rezolvat – fix livrat | M22: 3.7.0 | N22: 46172 | P22: =IF(N22="","",N22-B22) -> 16 | Q22: Echipa Rambursări | S22: refund not received; refund pending weeks; still waiting for refund
A23: WB-1022 | B23: 46164 | C23: Call center | D23: Check-in | E23: Boarding pass | F23: Codul QR de pe boarding pass nu e citit la poartă | G23: Codul QR de pe boarding pass e prea șters (contrast prea mic). Scannerele de la poartă nu îl citesc. | H23: 1. Deschide pagina „Check-in” (/check-in). 2. Introdu codul rezervării HNY42K și numele Ionescu, apoi apasă „Caută rezervarea”. 3. Apasă „Fă check-in pentru pasager”. Rezultat așteptat: pe boarding pass, codul QR („Cod de îmbarcare”) are pătrățele închise la culoare pe fundal alb, cu contrast ridicat, ușor de scanat. | I23: Mare | J23: 43 | K23: 3.6.0 | L23: Rezolvat – fix livrat | M23: 3.8.0 | N23: 46191 | P23: =IF(N23="","",N23-B23) -> 27 | Q23: Echipa Mobile | S23: boarding pass qr not scanning; gate scanner rejected; dark mode boarding pass
A24: WB-1023 | B24: 46186 | C24: Web | D24: Plăți | E24: Plată card | F24: Plata e respinsă, dar suma e blocată pe card | G24: Clientul vede „Plată eșuată”, dar rezervarea apare totuși în „Călătoriile mele”. Clientul reîncearcă și ajunge să plătească de două ori. | I24: Critică | J24: 362 | K24: 3.7.0 | L24: Rezolvat – fix livrat | M24: 3.9.0 | N24: 46213 | P24: =IF(N24="","",N24-B24) -> 27 | Q24: Echipa Plăți | R24: WB-1009 | S24: payment failed but charged; double charged; money taken booking failed
A25: WB-1024 | B25: 46189 | C25: Web | D25: Rezervare | E25: Selecție locuri | F25: Familiile sunt așezate separat deși au plătit locuri | G25: Locurile alese pentru copii sunt reatribuite la check-in, iar copiii ajung separați de părinți. | I25: Mare | J25: 396 | K25: 3.7.0 | L25: Rezolvat – fix livrat | M25: 3.10.0 | N25: 46232 | P25: =IF(N25="","",N25-B25) -> 43 | Q25: Echipa Rezervări | R25: WB-1017 | S25: family seated apart; kids separated from parents; paid seats changed
A26: WB-1025 | B26: 46192 | C26: Web | D26: Aplicație | E26: Performanță | F26: Încărcare lentă a paginii de plată pe web | G26: Pe site, pagina de plată se încarcă în 8–12 secunde și unii clienți abandonează rezervarea. | I26: Medie | J26: 32 | K26: 3.8.0 | L26: Închis – nu se reproduce | O26: 46200 | P26: =IF(N26="","",N26-B26) | Q26: Echipa Web | S26: website slow; checkout page slow; website keeps loading
A27: WB-1026 | B27: 46193 | C27: Web | D27: Suport | E27: Chat | F27: Asistentul chat repetă aceleași răspunsuri și nu transferă la un agent | G27: Asistentul chat de pe site nu oferă opțiunea de a vorbi cu un agent, iar clientul rămâne blocat. | I27: Mare | J27: 388 | K27: 3.8.0 | L27: Rezolvat – fix livrat | M27: 3.10.0 | N27: 46232 | P27: =IF(N27="","",N27-B27) -> 39 | Q27: Echipa Suport | S27: customer service chat bot useless; can't reach human; no customer support
A28: WB-1027 | B28: 46210 | C28: Call center | D28: Check-in | E28: Check-in online | F28: Check-in-ul online eșuează pentru grupuri de peste 4 pasageri | G28: La finalizarea check-in-ului pentru 5+ pasageri apare eroarea „Ceva nu a mers bine”. Pasagerii sunt trimiși la ghișeu și plătesc taxa de check-in în aeroport. | H28: 1. Deschide pagina „Check-in” (/check-in). 2. Introdu codul rezervării BEE5X2 și numele Popescu, apoi apasă „Caută rezervarea”. 3. Apasă „Fă check-in pentru toți cei 6 pasageri”. Rezultat așteptat: apare mesajul „Check-in făcut” și boarding pass-urile pentru toți cei 6 pasageri; nu apare eroarea „Ceva nu a mers bine” (cod CHK-500). | I28: Critică | J28: 115 | K28: 3.8.0 | L28: Rezolvat – fix livrat | M28: 3.11.0 | N28: 46251 | P28: =IF(N28="","",N28-B28) -> 41 | Q28: Echipa Check-in | S28: online check-in failed; check-in error group; forced airport check-in fee
A29: WB-1028 | B29: 46210 | C29: Rețele sociale | D29: Bagaje | E29: Dimensiuni bagaj | F29: Ghidul de dimensiuni pentru bagajul de mână e neclar | G29: Pagina de bagaje nu arată clar diferența dintre geanta mică gratuită și trolerul de 10 kg. Clienții plătesc taxe la poartă. | I29: Mică | J29: 75 | K29: 3.8.0 | L29: În lucru | P29: =IF(N29="","",N29-B29) | Q29: Echipa Conținut | R29: WB-1020 | S29: cabin bag size; carry-on fee at gate; hand luggage charged gate
A30: WB-1029 | B30: 46211 | C30: Email | D30: Rezervare | E30: Selecție locuri | F30: Harta de locuri nu se încarcă pentru zborurile cu A321neo | G30: La aeronavele A321neo harta rămâne goală și clientul nu poate alege loc. | H30: 1. Pe pagina principală caută zboruri București (OTP) → Barcelona (BCN), data 2026-11-13, 1 pasager. 2. Alege zborul WB 541 (A321neo). 3. Completează numele pasagerului, apasă „Continuă” până la pasul „Locuri”. Rezultat așteptat: harta locurilor se afișează și un loc poate fi selectat; nu rămâne blocată la „Se încarcă harta locurilor…”. | I30: Mare | J30: 35 | K30: 3.8.0 | L30: Rezolvat – fix livrat | M30: 3.11.0 | N30: 46251 | P30: =IF(N30="","",N30-B30) -> 40 | Q30: Echipa Rezervări | R30: WB-1016 | S30: seat map not loading; can't select seat; seat selection error
A31: WB-1030 | B31: 46212 | C31: Call center | D31: Notificări | E31: Întârzieri | F31: Avertizarea de întârziere nu apare la zborurile întârziate peste 3 ore | G31: În pagina rezervării nu apare avertizarea de întârziere și nici link-ul pentru cererea de compensație, deși zborul are peste 3 ore întârziere. | I31: Mare | J31: 100 | K31: 3.8.0 | L31: Rezolvat – fix livrat | M31: 3.10.0 | N31: 46232 | P31: =IF(N31="","",N31-B31) -> 20 | Q31: Echipa Operațiuni Digitale | R31: WB-1018 | S31: no delay notice; delay not shown; compensation link missing
A32: WB-1031 | B32: 46214 | C32: Web | D32: Rambursări | E32: Cerere rambursare | F32: Cererile de rambursare rămân „În procesare” peste 30 de zile | G32: După anularea zborului, cererile de rambursare nu trec de starea „În procesare”. Clienții nu primesc nicio actualizare. | I32: Critică | J32: 393 | K32: 3.9.0 | L32: Rezolvat – fix livrat | M32: 3.11.0 | N32: 46251 | P32: =IF(N32="","",N32-B32) -> 37 | Q32: Echipa Rambursări | R32: WB-1021 | S32: refund not received; refund pending weeks; still waiting for refund
A33: WB-1032 | B33: 46214 | C33: Web | D33: Aplicație | E33: Performanță | F33: Încărcare lentă a paginii de plată pe web | G33: Pe site, pagina de plată se încarcă în 8–12 secunde și unii clienți abandonează rezervarea. | I33: Medie | J33: 55 | K33: 3.9.0 | L33: Rezolvat – fix livrat | M33: 3.10.0 | N33: 46232 | P33: =IF(N33="","",N33-B33) -> 18 | Q33: Echipa Web | R33: WB-1025 | S33: website slow; checkout page slow; website keeps loading
A34: WB-1033 | B34: 46214 | C34: Rețele sociale | D34: Abonamente | E34: BeeClub | F34: Reducerea BeeClub nu se aplică la bagaje | G34: Membrii BeeClub nu primesc reducerea promisă la bagajul de cală. | I34: Mică | J34: 63 | K34: 3.9.0 | L34: Rezolvat – fix livrat | M34: 3.11.0 | N34: 46251 | P34: =IF(N34="","",N34-B34) -> 37 | Q34: Echipa Ancillaries | S34: discount club not applied; membership discount; club price not working
A35: WB-1034 | B35: 46221 | C35: Web | D35: Cont | E35: Autentificare | F35: Butonul „Retrimite codul” din pagina de autentificare nu funcționează | G35: La autentificarea cu cod OTP, butonul „Retrimite codul” nu face nimic. Dacă primul cod a expirat, clientul nu se mai poate conecta. | I35: Mare | J35: 340 | K35: 3.9.0 | L35: Rezolvat – fix livrat | M35: 3.11.0 | N35: 46251 | P35: =IF(N35="","",N35-B35) -> 30 | Q35: Echipa Identitate | S35: resend code not working; can't log in; OTP code expired no resend
A36: WB-1035 | B36: 46227 | C36: Email | D36: Plăți | E36: Plată card | F36: Plata e respinsă, dar suma e blocată pe card | G36: Clientul vede „Plată eșuată”, dar rezervarea apare totuși în „Călătoriile mele”. Clientul reîncearcă și ajunge să plătească de două ori. | I36: Critică | J36: 376 | K36: 3.9.0 | L36: Rezolvat – fix livrat | M36: 3.12.0 | N36: 46270 | P36: =IF(N36="","",N36-B36) -> 43 | Q36: Echipa Plăți | R36: WB-1023 | S36: payment failed but charged; double charged; money taken booking failed
A37: WB-1036 | B37: 46236 | C37: Email | D37: Check-in | E37: Boarding pass | F37: Codul QR de pe boarding pass nu e citit la poartă | G37: Codul QR de pe boarding pass e prea șters (contrast prea mic). Scannerele de la poartă nu îl citesc. | H37: 1. Deschide pagina „Check-in” (/check-in). 2. Introdu codul rezervării HNY42K și numele Ionescu, apoi apasă „Caută rezervarea”. 3. Apasă „Fă check-in pentru pasager”. Rezultat așteptat: pe boarding pass, codul QR („Cod de îmbarcare”) are pătrățele închise la culoare pe fundal alb, cu contrast ridicat, ușor de scanat. | I37: Mare | J37: 188 | K37: 3.10.0 | L37: Rezolvat – fix livrat | M37: 3.12.0 | N37: 46270 | P37: =IF(N37="","",N37-B37) -> 34 | Q37: Echipa Mobile | R37: WB-1022 | S37: boarding pass qr not scanning; gate scanner rejected; dark mode boarding pass
A38: WB-1037 | B38: 46253 | C38: Web | D38: Aplicație | E38: Performanță | F38: Încărcare lentă a paginii de plată pe web | G38: Pe site, pagina de plată se încarcă în 8–12 secunde și unii clienți abandonează rezervarea. | I38: Medie | J38: 57 | K38: 3.11.0 | L38: Rezolvat – fix livrat | M38: 3.12.0 | N38: 46270 | P38: =IF(N38="","",N38-B38) -> 17 | Q38: Echipa Web | R38: WB-1032 | S38: website slow; checkout page slow; website keeps loading
A39: WB-1038 | B39: 46270 | C39: Web | D39: Abonamente | E39: BeeClub | F39: Reducerea BeeClub nu se aplică la bagaje | G39: Membrii BeeClub nu primesc reducerea promisă la bagajul de cală. | I39: Mică | J39: 75 | K39: 3.12.0 | L39: Rezolvat – fix livrat | M39: 3.13.0 | N39: 46290 | P39: =IF(N39="","",N39-B39) -> 20 | Q39: Echipa Ancillaries | R39: WB-1033 | S39: discount club not applied; membership discount; club price not working
A40: WB-1039 | B40: 46271 | C40: Email | D40: Rambursări | E40: Cerere rambursare | F40: Cererile de rambursare rămân „În procesare” peste 30 de zile | G40: După anularea zborului, cererile de rambursare nu trec de starea „În procesare”. Clienții nu primesc nicio actualizare. | I40: Critică | J40: 3 | K40: 3.12.0 | L40: Rezolvat – fix livrat | M40: 3.14.0 | N40: 46310 | P40: =IF(N40="","",N40-B40) -> 39 | Q40: Echipa Rambursări | R40: WB-1031 | S40: refund not received; refund pending weeks; still waiting for refund
...

Sheet Release-uri
A1: Versiune | B1: Data lansării | C1: Platforme | D1: Tichete rezolvate | E1: Nr. fix-uri | F1: Funcționalitate nouă
A2: 3.0.0 | B2: 46034 | C2: Web | E2: =COUNTIF(Tichete!$M$2:$M$47,A2) -> 0 | F2: Hartă de locuri redesenată, cu filtru pentru locuri lângă ieșire
A3: 3.1.0 | B3: 46053 | C3: Web | D3: WB-1001 | E3: =COUNTIF(Tichete!$M$2:$M$47,A3) -> 1 | F3: Boarding pass descărcabil în format PDF
A4: 3.2.0 | B4: 46072 | C4: Web | E4: =COUNTIF(Tichete!$M$2:$M$47,A4) -> 0 | F4: Plată în rate pentru rezervări peste 500 €
A5: 3.3.0 | B5: 46093 | C5: Web | D5: WB-1002, WB-1003, WB-1005 | E5: =COUNTIF(Tichete!$M$2:$M$47,A5) -> 3 | F5: Actualizare automată a porții în „Status zbor”
A6: 3.4.0 | B6: 46113 | C6: Web | E6: =COUNTIF(Tichete!$M$2:$M$47,A6) -> 0 | F6: Abonament BeeClub cu reducere la bagaje
A7: 3.5.0 | B7: 46133 | C7: Web | D7: WB-1006 | E7: =COUNTIF(Tichete!$M$2:$M$47,A7) -> 1 | F7: Alegerea mesei calde la rezervare
A8: 3.6.0 | B8: 46153 | C8: Web | D8: WB-1008, WB-1009, WB-1010, WB-1011, WB-1015 | E8: =COUNTIF(Tichete!$M$2:$M$47,A8) -> 5 | F8: Mod întunecat pe site
A9: 3.7.0 | B9: 46172 | C9: Web | D9: WB-1014, WB-1017, WB-1018, WB-1021 | E9: =COUNTIF(Tichete!$M$2:$M$47,A9) -> 4 | F9: Check-in automat cu 48h înainte
A10: 3.8.0 | B10: 46191 | C10: Web | D10: WB-1016, WB-1020, WB-1022 | E10: =COUNTIF(Tichete!$M$2:$M$47,A10) -> 3 | F10: Asistență specială (PRM) direct de pe site
A11: 3.9.0 | B11: 46213 | C11: Web | D11: WB-1023 | E11: =COUNTIF(Tichete!$M$2:$M$47,A11) -> 1 | F11: Istoric rezervări cu export PDF
A12: 3.10.0 | B12: 46232 | C12: Web | D12: WB-1024, WB-1026, WB-1030, WB-1032 | E12: =COUNTIF(Tichete!$M$2:$M$47,A12) -> 4 | F12: Comparare tarife pe 7 zile
A13: 3.11.0 | B13: 46251 | C13: Web | D13: WB-1027, WB-1029, WB-1031, WB-1033, WB-1034 | E13: =COUNTIF(Tichete!$M$2:$M$47,A13) -> 5 | F13: Transfer de nume pe bilet din cont
A14: 3.12.0 | B14: 46270 | C14: Web | D14: WB-1035, WB-1036, WB-1037 | E14: =COUNTIF(Tichete!$M$2:$M$47,A14) -> 3 | F14: Portofel BeeCredit pentru rambursări
A15: 3.13.0 | B15: 46290 | C15: Web | D15: WB-1038 | E15: =COUNTIF(Tichete!$M$2:$M$47,A15) -> 1 | F15: Asistent chat pentru întrebări despre bagaje
A16: 3.14.0 | B16: 46310 | C16: Web | D16: WB-1039 | E16: =COUNTIF(Tichete!$M$2:$M$47,A16) -> 1 | F16: Plată cu Apple Pay și Google Pay

Sheet Sumar
A1: Sumar tichete Wizz Bees
A3: Total tichete | B3: =COUNTA(Tichete!$A$2:$A$47) -> 46
A4: Rezolvat – fix livrat | B4: =COUNTIF(Tichete!$L$2:$L$47,A4) -> 32
A5: În lucru | B5: =COUNTIF(Tichete!$L$2:$L$47,A5) -> 5
A6: Nou | B6: =COUNTIF(Tichete!$L$2:$L$47,A6) -> 5
A7: Închis – nu se reproduce | B7: =COUNTIF(Tichete!$L$2:$L$47,A7) -> 4
A9: Redeschise / raportate din nou | B9: =COUNTIF(Tichete!$R$2:$R$47,"<>") -> 21
A10: Rată de redeschidere (din fix-urile livrate) | B10: =IF(B4=0,0,B9/B4) -> 0.65625 | C10: Câte fix-uri au fost urmate de o nouă raportare pe aceeași problemă
A11: Medie zile până la fix | B11: =IFERROR(AVERAGE(Tichete!$P$2:$P$47),0) -> 30.15625
A13: Categorie | B13: Tichete | C13: Fix livrat | D13: Redeschise / raportate din nou | E13: Raportări clienți
A14: Abonamente | B14: =COUNTIF(Tichete!$D$2:$D$47,A14) -> 2 | C14: =COUNTIFS(Tichete!$D$2:$D$47,A14,Tichete!$L$2:$L$47,"Rezolvat – fix livrat") -> 2 | D14: =COUNTIFS(Tichete!$D$2:$D$47,A14,Tichete!$R$2:$R$47,"<>") -> 1 | E14: =SUMIF(Tichete!$D$2:$D$47,A14,Tichete!$J$2:$J$47) -> 138
A15: Aplicație | B15: =COUNTIF(Tichete!$D$2:$D$47,A15) -> 5 | C15: =COUNTIFS(Tichete!$D$2:$D$47,A15,Tichete!$L$2:$L$47,"Rezolvat – fix livrat") -> 3 | D15: =COUNTIFS(Tichete!$D$2:$D$47,A15,Tichete!$R$2:$R$47,"<>") -> 2 | E15: =SUMIF(Tichete!$D$2:$D$47,A15,Tichete!$J$2:$J$47) -> 526
A16: Asistență specială | B16: =COUNTIF(Tichete!$D$2:$D$47,A16) -> 1 | C16: =COUNTIFS(Tichete!$D$2:$D$47,A16,Tichete!$L$2:$L$47,"Rezolvat – fix livrat") -> 0 | D16: =COUNTIFS(Tichete!$D$2:$D$47,A16,Tichete!$R$2:$R$47,"<>") -> 0 | E16: =SUMIF(Tichete!$D$2:$D$47,A16,Tichete!$J$2:$J$47) -> 87
A17: Bagaje | B17: =COUNTIF(Tichete!$D$2:$D$47,A17) -> 4 | C17: =COUNTIFS(Tichete!$D$2:$D$47,A17,Tichete!$L$2:$L$47,"Rezolvat – fix livrat") -> 2 | D17: =COUNTIFS(Tichete!$D$2:$D$47,A17,Tichete!$R$2:$R$47,"<>") -> 2 | E17: =SUMIF(Tichete!$D$2:$D$47,A17,Tichete!$J$2:$J$47) -> 205
A18: Check-in | B18: =COUNTIF(Tichete!$D$2:$D$47,A18) -> 9 | C18: =COUNTIFS(Tichete!$D$2:$D$47,A18,Tichete!$L$2:$L$47,"Rezolvat – fix livrat") -> 4 | D18: =COUNTIFS(Tichete!$D$2:$D$47,A18,Tichete!$R$2:$R$47,"<>") -> 4 | E18: =SUMIF(Tichete!$D$2:$D$47,A18,Tichete!$J$2:$J$47) -> 1012
A19: Cont | B19: =COUNTIF(Tichete!$D$2:$D$47,A19) -> 4 | C19: =COUNTIFS(Tichete!$D$2:$D$47,A19,Tichete!$L$2:$L$47,"Rezolvat – fix livrat") -> 2 | D19: =COUNTIFS(Tichete!$D$2:$D$47,A19,Tichete!$R$2:$R$47,"<>") -> 2 | E19: =SUMIF(Tichete!$D$2:$D$47,A19,Tichete!$J$2:$J$47) -> 957
A20: Notificări | B20: =COUNTIF(Tichete!$D$2:$D$47,A20) -> 4 | C20: =COUNTIFS(Tichete!$D$2:$D$47,A20,Tichete!$L$2:$L$47,"Rezolvat – fix livrat") -> 3 | D20: =COUNTIFS(Tichete!$D$2:$D$47,A20,Tichete!$R$2:$R$47,"<>") -> 2 | E20: =SUMIF(Tichete!$D$2:$D$47,A20,Tichete!$J$2:$J$47) -> 781
A21: Plăți | B21: =COUNTIF(Tichete!$D$2:$D$47,A21) -> 4 | C21: =COUNTIFS(Tichete!$D$2:$D$47,A21,Tichete!$L$2:$L$47,"Rezolvat – fix livrat") -> 4 | D21: =COUNTIFS(Tichete!$D$2:$D$47,A21,Tichete!$R$2:$R$47,"<>") -> 2 | E21: =SUMIF(Tichete!$D$2:$D$47,A21,Tichete!$J$2:$J$47) -> 913
A22: Rambursări | B22: =COUNTIF(Tichete!$D$2:$D$47,A22) -> 5 | C22: =COUNTIFS(Tichete!$D$2:$D$47,A22,Tichete!$L$2:$L$47,"Rezolvat – fix livrat") -> 5 | D22: =COUNTIFS(Tichete!$D$2:$D$47,A22,Tichete!$R$2:$R$47,"<>") -> 3 | E22: =SUMIF(Tichete!$D$2:$D$47,A22,Tichete!$J$2:$J$47) -> 897
A23: Rezervare | B23: =COUNTIF(Tichete!$D$2:$D$47,A23) -> 7 | C23: =COUNTIFS(Tichete!$D$2:$D$47,A23,Tichete!$L$2:$L$47,"Rezolvat – fix livrat") -> 6 | D23: =COUNTIFS(Tichete!$D$2:$D$47,A23,Tichete!$R$2:$R$47,"<>") -> 3 | E23: =SUMIF(Tichete!$D$2:$D$47,A23,Tichete!$J$2:$J$47) -> 958
A24: Suport | B24: =COUNTIF(Tichete!$D$2:$D$47,A24) -> 1 | C24: =COUNTIFS(Tichete!$D$2:$D$47,A24,Tichete!$L$2:$L$47,"Rezolvat – fix livrat") -> 1 | D24: =COUNTIFS(Tichete!$D$2:$D$47,A24,Tichete!$R$2:$R$47,"<>") -> 0 | E24: =SUMIF(Tichete!$D$2:$D$47,A24,Tichete!$J$2:$J$47) -> 388

Sheet Legendă
A1: Ce este | B1: Tichete de suport fictive pentru Wizz Bees, o companie aeriană inventată pentru demo-ul de la hackathon. Toate datele sunt mock.
A2: Cum se leagă de aplicație | B2: Toate tichetele privesc site-ul web Wizz Bees. Fiecare tichet „Rezolvat – fix livrat” apare și în pagina „Noutăți” a site-ului, la versiunea din coloana „Versiune fix”.
A3: Pentru Provocarea 2 | B3: Aplicația de reviews ia „Data livrării fix-ului” și „Cuvinte cheie recenzii (EN)” și caută recenzii publice de după acea dată. Dacă problema mai apare, fix-ul nu a funcționat.
A4: Tichete legate | B4: Tichete deschise din nou pentru aceeași problemă (după un fix livrat sau ca raportare duplicat). Titlul nu mai conține prefixe; legătura se vede doar în coloana „Tichet legat”, ca deduplicarea cu embeddings să poată fi verificată pe ea.
A5: Ce puteți edita | B5: Orice coloană din foaia Tichete, cu excepția „Zile până la fix” (formulă). Status și Severitate au liste derulante.
A6: Rânduri noi | B6: Adăugați sub ultimul rând. Formulele din Sumar acoperă doar rândurile existente; extindeți intervalele dacă adăugați multe tichete.
A7: Regenerare | B7: Fișier editat manual după generare; nu mai rulați scripturile de generare peste el.
A8: Pași de verificare | B8: Scriși de developer când livrează fix-ul. AI Testing Agent îi transformă într-un plan Playwright și îi rulează periodic pe tichetele „Rezolvat – fix livrat”. Au pași doar tichetele ale căror bug-uri există în Wizz Bees (src/data/bugs.js). Un tichet „Rezolvat – fix livrat” fără pași apare în dashboard ca „Necesită verificare manuală”.
A9: Severitate | B9: Valorile existente sunt cele decise de LLM la extracție. La un tichet nou, lăsați coloana goală: LLM-ul o completează la import.
A10: Status după verificare | B10: Test trecut → statusul rămâne „Rezolvat – fix livrat”. Test picat → „În lucru”, cu data de azi. „Nou”, „În lucru” și „Închis – nu se reproduce” nu sunt testate.
A11: Date de test | B11: Pașii folosesc rezervările de demo și zborurile deterministe din Wizz Bees; lista e în foaia „Date de test”. Agentul pornește fiecare test într-un browser curat (localStorage gol), altfel un check-in reușit rămâne salvat.

Sheet Date de test
A1: Tip | B1: Valoare | C1: Folosit de | D1: Ce conține
A2: Rezervare | B2: BEE5X2 / Popescu | C2: WB-1027, WB-1040 | D2: Grup de 6 pasageri, zbor WB 412 (A321neo); check-in neefectuat
A3: Rezervare | B3: HNY42K / Ionescu | C3: WB-1022, WB-1036, WB-1042 | D3: Un pasager, zbor WB 233; check-in neefectuat
A4: Zbor | B4: OTP → BCN, 2026-11-13, WB 541 | C4: WB-1008, WB-1013, WB-1016, WB-1029 | D4: Singurul zbor al zilei, operat cu A321neo; bagaj de cală 20 kg = 189 lei
A5: Versiune | B5: Selectorul „Versiunea aplicației” din footer | C5: toate | D5: Versiunea curentă e 3.14.0. Bug-urile apar/dispar după versiune (src/data/bugs.js); localStorage „wb.version”
